<mujoco>
	<option gravity="0 0 -9.81">
		<flag sensornoise="enable" energy="enable"/>
	</option>

	<worldbody>
		<light diffuse=".5 .5 .5" pos="0 0 3" dir="0 0 -1"/>
    	<geom type="plane" size="100 100 0.1" rgba="0.5 0.5 0.5 1"/>
		<body pos="0 0 2" euler="0 0 0">
			<joint name="J0" type="hinge" axis="0 -1 0" pos="0 0 0.5"/>
			<geom type="cylinder" size=".05 .5" rgba="0 .9 0 1" mass="1"/>
		</body>
	</worldbody>
	<actuator>
		<motor joint="J0" name="torque" gear="1" ctrllimited="true" ctrlrange="-100 100"/>
	</actuator>
	<sensor>
		<jointpos joint="J0" noise="0.2"/>
		<jointvel joint="J0" noise="1"/>
	</sensor>
</mujoco>
